Workbook

Sheet Revision History
A1: Revision | B1: Date | C1: Name | D1: Description
A2: 0.1
A3: 0.2 | B3: 2017-11-02 | C3: Simon Gallimore | D3: Updated formating after feedback. Fixed VREF fields and added additional SRAM fields.
A4: 0.3 | B4: 2017-11-06 | C4: Simon Gallimore | D4: Updates after feedback from integration.
A5: 0.4 | B5: 2017-11-30 | C5: Simon Gallimore | D5: Updated with SCG and SPC details.
A6: 0.5 | B6: 2018-01-26 | C6: Simon Gallimore | D6: Reorganized to push SRAM repair to last IFR fields, added phantom fields, added device ID field.
A7: 0.6 | B7: 2018-04-11 | C7: Simon Gallimore | D7: Updated with new SCG, SPC, MTR, RF fields.
A8: 0.7 | B8: 2018-08-03 | C8: Simon Gallimore | D8: Updated for K4F1 with new SPC fields.
A9: 0.8 | B9: 2018-08-24 | C9: Simon Gallimore | D9: Updated with new SPC and MTR Repair fields.
A10: 0.9 | B10: 2018-09-12 | C10: Simon Gallimore | D10: Updated CMC trim for SRAM read/write margin/assist, added USB VREG trim and updated SPC trims.
A11: 0.10 | B11: 2018-09-19 | C11: Simon Gallimore | D11: Updated SRAM instance names
A12: 0.11 | B12: 2018-09-25 | C12: Simon Gallimore | D12: Updated SRAM pin names
A13: 0.12 | B13: 2018-10-11 | C13: Simon Gallimore | D13: Updated SRAM pin names
A14: 0.12 | B14: 2018-11-01 | C14: Simon Gallimore | D14: Fixed typo
A15: 1.0 | B15: 2019-08-26 | C15: Simon Gallimore | D15: Updated with MSF trim fields from Brian Cook
... A25: 0.09 | B25: 2021-9-1 | C25: Eric Wu | D25: Update default value of soctrim0~7 Update the connection of DEVICE ID/DEVICE TYPE/DIE ID
A26: 0.1 | B26: 2021-9-2 | C26: Eric Wu | D26: Update USB HS PHY default trim value
A27: 0.11 | B27: 2021-9-6 | C27: Eric Wu | D27: update MSF default trim values based on NMV team's feedback.
A28: 0.12 | B28: 2021-9-9 | C28: Durgesh Pattamatta | D28: Updated IFR0 flash address values.
A29: 0.13 | B29: 2021-9-15 | C29: Eric Wu | D29: Add nirvana1_phantom table to show registers' configuration in different phantom options
A30: 0.14 | B30: 2021-10-12 | C30: Eric Wu | D30: In phantom table, Nxx2,Nxx4,Nxx3 and Nxx1 RAM size configuration should be same
A31: 0.15 | B31: 2021-10-13 | C31: Durgesh Pattamatta | D31: Added non-secure IFR0 worksheet.
A32: 0.15 | B32: 2021-11-10 | C32: Eric Wu | D32: In RTL, soctrim0[87:80] is connected to syscon_device_id0[7:0]
A33: 0.16 | B33: 2021-11-18 | C33: Eric Wu | D33: Updated SPC soctrim default vaule based on SoC team's latest configuration. Updated nirvana1_phantom table basedon marketing's latest udpate on part number configuration. And fix an error of S50 configuartion in non-secure part
A34: 0.17 | B34: 2021-11-18 | C34: Saurabh Jagdhane | D34: Updated byte order of Root of Trust Keys Table hash to align with fusemap.
A35: 0.18 | B35: 2021-11-18 | C35: Eric Wu | D35: Add address information of scotrim1 in nirvana1_phantom table.
A36: 0.18 | B36: 44518 | C36: Eric Wu | D36: Add part number columns in nirvana1_ifr1 table
A37: 0.19 | B37: 44544 | C37: Eric Wu | D37: Fix the address error of Peripheral_EN and MISC_Phantom in nirvana1_phantom table, to align with nirvana1_ifr1 table
A38: 0.2 | B38: 44565 | C38: Eric Wu | D38: CM33_CFG_SEC_EXT[3:0] is 0xA in non-secure phantom
A39: 0.21 | B39: 44567 | C39: Eric Wu | D39: Enable S50/OPTC/GDET0,1 in ns phantom per ROM teams requiremnt
A40: 0.22 | B40: 44601 | C40: Eric Wu | D40: There is 1x CAN in NX3xx, NX5xx, and FD is disabled in NX3xx Prince and IPED should be disabled in NS phantom
A41: 0.23 | B41: 44601 | C41: Durgesh Pattamatta | D41: Added ISP_USB_CUST field to CMPA section.
C42: Eric Wu | D42: Split FRO16 trim to freq and temp trim per PE/TE's request. Change line 168 to spc_coreldo_vtrim_underdrive(middrive)_ifr_value
C43: Eric Wu | D43: Split tamper field to individual trim per PE/TE's request
A44: 0.24 | B44: 44803 | C44: Roy Chen | D44: Delete the UART_BAUD_RATE and Update the CAN_BAUD_RATE note.
A45: 0.25 | B45: 16/10/2022 | C45: Alex Qiu | D45: Add the REC_BOOT_PIN_CUST field in CMPA for recovery boot pin resetting
A46: 0.26 | B46: 44987 | C46: Eric Wu | D46: spc_coreldo_cfg_idrv_sel_ifr_value is updated to 4'h6 to provide 100mA (120mA at hot temperature) drive strength SOCTRIM5[49:48] controls SRAM read_assist pin in MD mode. It is updated to 2'b01 in TS_CLN40ULPEF_NXP_EDLVSPRAM compiler 1.01.00
A47: 0.27 | B47: 44972 | C47: Durgesh Pattamatta | D47: Added "GDET config" worksheet. Added "EXT_VOLT_SEL" field in CMPA for initial GDET configuration mode selection.
A48: 0.28 | B48: 44991 | C48: Durgesh Pattamatta | D48: Added description for fields reported in SE review for UM release.
A49: 0.29 | B49: 45019 | C49: Durgesh Pattamatta | D49: Added "TRNG config" worksheet.
...

Sheet Flash layout
G8: Start Address
G9: 0x0000_0000 | H9: Bank0_user - Image 0
M10: Regular flash programmable through APB & AHB register interface
M11: Indexed flash only programmable through FMU Test port registers. Available only during NXP lifecycle states.
H17: Bank0_unswaped
G20: 0x0010_0000 | H20: Bank 1 - Image 1
H25: Bank1_unswapped
G30: 0x0100_0000 | H30: Bank0_IFR0_CFPA_0 (8KB)
G31: 0x0100_2000 | H31: Bank0_IFR0_CFPA_1 (8KB)
G32: 0x0100_4000 | H32: Bank0_IFR0_CMPA (8KB)
G33: 0x0100_6000 | H33: Bank0_IFR0_NMPA (8KB) | I33: NXP ROM extension: - OSCCA boot, - EL2GO service library: infield provisioning, MAD recovery - NXP CMAC (last 128 bits)
G34: 0x0100_8000 | H34: SBL - Bank1_IFR0 (32KB) | I34: Customer RoT or NXP recovery - ECDSA verify (Cust_RoT, Cust) - Direct_boot selectable by OTP field - Similar to Bank0_IFR0 four separate 8KB MBC sectors are present to configure access control permissions.
G36: 0x0110_0000 | H36: Bank0_IFR1_VISIBLE (4KB) | I36: Trim + ROM patch + PUF helper data Only programmable by ATE | L36: 0x02010000 - 0x02010C00 | M36: Identity data- Activation
L37: 0x02010C00 - 0x020117FF | M37: MSF array 0 + Test data
H38: Bank0_IFR1_HIDDEN(4KB) | L38: 0x02011800 - 0x020118FF | M38: Soc Trim
K39: 1.5K | L39: 0x02011900 - 0x02012000 | M39: ROM patch
G40: 0x0110_2000 | H40: Bank1_IFR1_HIDDEN (8KB) | K40: 3KB | L40: 0x02012000 - 0x02012DFF | M40: ROM patch
L41: 0x02012E00 - 0x02012FFF | M41: MSF array 1 + Test data
K42: 4KB | L42: 0x02013000 - 0x02013FFF | M42: ROM patch 2

Sheet IFR0 (customer 2P02G)
A1: Protected Flash Region | E1: 31 | F1: =E1-1 -> 30 | G1: =F1-1 -> 29 | H1: =G1-1 -> 28 | I1: =H1-1 -> 27 | J1: =I1-1 -> 26 | K1: =J1-1 -> 25 | L1: =K1-1 -> 24 | M1: =L1-1 -> 23 | ... AJ1: =AI1-1 -> 0
E3: +3 | M3: +2 | U3: +1 | AC3: +0
E4: 31 | F4: =E4-1 -> 30 | G4: =F4-1 -> 29 | H4: =G4-1 -> 28 | I4: =H4-1 -> 27 | J4: =I4-1 -> 26 | K4: =J4-1 -> 25 | L4: =K4-1 -> 24 | M4: =L4-1 -> 23 | ... AJ4: =AI4-1 -> 0
B5: Word Address (HEX) | C5: Byte Address (HEX) | D5: Field Description
A6: Customer Field Programmable Area (CFPA) | B6: 100000 | C6: =DEC2HEX(HEX2DEC($B$6)*16, 8) -> 01000000 | D6: Header | E6: Header | U6: INV_CFPA_LC_STATE[7:0] | AC6: CFPA_LC_STATE[7:0]
C7: =DEC2HEX(HEX2DEC(C6) + 4, 8) -> 01000004 | D7: CFPA_PAGE_VERSION | E7: DICE_UPD | F7: DICE_KEY_UPD_ALIAS | G7: CMPA_UPD | J7: Reserved | K7: IMG_UPD | M7: CFPA page version (Monotonic counter)
C8: =DEC2HEX(HEX2DEC(C7) + 4, 8) -> 01000008 | D8: Secure_FW_Version | E8: Reserved | U8: Secure firmware version (Monotonic counter)
C9: =DEC2HEX(HEX2DEC(C8) + 4, 8) -> 0100000C | D9: NS_FW_Version | E9: Non Secure firmware version (Monotonic counter)
B10: =DEC2HEX(HEX2DEC(B6) + 1) -> 100001 | C10: =DEC2HEX(HEX2DEC(C9) + 4, 8) -> 01000010 | D10: reserved | E10: Reserved for future use.
C11: =DEC2HEX(HEX2DEC(C10) + 4, 8) -> 01000014 | D11: SECBOOT_FLAGS | E11: OEM_RETURN_ERASE_DONE | I11: Reserved | AC11: RoTK3_EN | AE11: RoTK2_EN | AG11: RoTK1_EN | AI11: RoTK0_EN
C12: =DEC2HEX(HEX2DEC(C11) + 4, 8) -> 01000018 | D12: IMAGE_KEY_REVOKE | E12: RESERVED | M12: Image key revocation ID (Monotonic counter)
C13: =DEC2HEX(HEX2DEC(C12) + 4, 8) -> 0100001C | D13: LP_VECTOR_ADDR | E13: LP_VECTOR_ADDR
B14: =DEC2HEX(HEX2DEC(B10) + 1) -> 100002 | C14: =DEC2HEX(HEX2DEC(C13) + 4, 8) -> 01000020 | D14: DBG_REVOKE_VU | E14: Inverse value of [15:0] | U14: Debug certificate revocation counter (monotonic counter)
C15: =DEC2HEX(HEX2DEC(C14) + 4, 8) -> 01000024 | D15: DCFG_CC_SOCU_NS_PIN | E15: Inverse value of [15:0] | U15: UUID_CHECK | Z15: CPU1_DBGEN | AA15: CPU1_NIDEN | AB15: ME_CMD_EN | AC15: FA_CMD_EN | AD15: ISP_CMD_EN | AE15: DSP_DBGEN | AF15: 0 | AG15: SPIDEN | AH15: SPNIDEN | AI15: DBGEN | AJ15: NIDEN
C16: =DEC2HEX(HEX2DEC(C15) + 4, 8) -> 01000028 | D16: DCFG_CC_SOCU_NS_DFLT | E16: Inverse value of [15:0] | Z16: CPU1_DBGEN | AA16: CPU1_NIDEN | AB16: ME_CMD_EN | AC16: FA_CMD_EN | AD16: ISP_CMD_EN | AE16: DSP_DBGEN | AF16: 0 | AG16: SPIDEN | AH16: SPNIDEN | AI16: DBGEN | AJ16: NIDEN
C17: =DEC2HEX(HEX2DEC(C16) + 4, 8) -> 0100002C | D17: reserved | E17: Reserved
B18: =DEC2HEX(HEX2DEC(B14) + 1) -> 100003 | C18: =DEC2HEX(HEX2DEC(C17) + 4, 8) -> 01000030 | D18: MCTR_NPX_CTX0 | E18: Erase count for internal Prince region 0 (Monotonic counter)
C19: =DEC2HEX(HEX2DEC(C18) + 4, 8) -> 01000034 | D19: MCTR_NPX_CTX1 | E19: Erase count for internal Prince region 1 (Monotonic counter)
C20: =DEC2HEX(HEX2DEC(C19) + 4, 8) -> 01000038 | D20: MCTR_NPX_CTX2 | E20: Erase count for internal Prince region 2 (Monotonic counter)
C21: =DEC2HEX(HEX2DEC(C20) + 4, 8) -> 0100003C | D21: MCTR_NPX_CTX3 | E21: Erase count for internal Prince region 3 (Monotonic counter)
B22: =DEC2HEX(HEX2DEC(B18) + 1) -> 100004 | C22: =DEC2HEX(HEX2DEC(C21) + 4, 8) -> 01000040 | D22: MCTR_IPED_CTX0 | E22: Erase count for external Prince region 0 (Monotonic counter)
C23: =DEC2HEX(HEX2DEC(C22) + 4, 8) -> 01000044 | D23: MCTR_IPED_CTX1 | E23: Erase count for external Prince region 1 (Monotonic counter)
C24: =DEC2HEX(HEX2DEC(C23) + 4, 8) -> 01000048 | D24: MCTR_IPED_CTX2 | E24: Erase count for external Prince region 2 (Monotonic counter)
C25: =DEC2HEX(HEX2DEC(C24) + 4, 8) -> 0100004C | D25: MCTR_IPED_CTX3 | E25: Erase count for external Prince region 3 (Monotonic counter)
B26: =DEC2HEX(HEX2DEC(B22) + 1) -> 100005 | C26: =DEC2HEX(HEX2DEC(C25) + 4, 8) -> 01000050 | D26: MCTR_IPED_CTX4 | E26: Erase count for external Prince region 4 (Monotonic counter)
C27: =DEC2HEX(HEX2DEC(C26) + 4, 8) -> 01000054 | D27: MCTR_IPED_CTX5 | E27: Erase count for external Prince region 5 (Monotonic counter)
C28: =DEC2HEX(HEX2DEC(C27) + 4, 8) -> 01000058 | D28: MCTR_IPED_CTX6 | E28: Erase count for external Prince region 6 (Monotonic counter)
C29: =DEC2HEX(HEX2DEC(C28) + 4, 8) -> 0100005C | D29: MCTR_IPED_CTX7 | E29: Erase count for external Prince region 7 (Monotonic counter)
B30: =DEC2HEX(HEX2DEC(B26) + 1) -> 100006 | C30: =DEC2HEX(HEX2DEC(C29) + 4, 8) -> 01000060 | D30: ERR_AUTH_FAIL_COUNT | E30: Authentication failure counter during boot, SB3, debug authentication (Monotonic counter)
C31: =DEC2HEX(HEX2DEC(C30) + 4, 8) -> 01000064 | D31: ERR_ITRC_COUNT | E31: Tamper event counter (Any ITRC reset caused by tamper events such as WDT reset, CDOG reset, GDET reset, Tamper pin) (Monotonic counter)
C32: =DEC2HEX(HEX2DEC(C31) + 4, 8) -> 01000068 | D32: reserved | E32: Reserved for future use.
C33: =DEC2HEX(HEX2DEC(C32) + 4, 8) -> 0100006C | D33: reserved | E33: Reserved for future use.
B34: =DEC2HEX(HEX2DEC(B30) + 1) -> 100007 | C34: =DEC2HEX(HEX2DEC(C33) + 4, 8) -> 01000070 | D34: reserved | E34: Reserved for future use.
C35: =DEC2HEX(HEX2DEC(C34) + 4, 8) -> 01000074 | D35: reserved | E35: Reserved for future use.
C36: =DEC2HEX(HEX2DEC(C35) + 4, 8) -> 01000078 | D36: reserved | E36: Reserved for future use.
C37: =DEC2HEX(HEX2DEC(C36) + 4, 8) -> 0100007C | D37: reserved | E37: Reserved for future use.
B38: =DEC2HEX(HEX2DEC(B34) + 1) -> 100008 | C38: =DEC2HEX(HEX2DEC(C37) + 4, 8) -> 01000080 | D38: MCTR_CUST_CTR0 | E38: Customer defined Monotonic counter 0
C39: =DEC2HEX(HEX2DEC(C38) + 4, 8) -> 01000084 | D39: MCTR_CUST_CTR1 | E39: Customer defined Monotonic counter 1
C40: =DEC2HEX(HEX2DEC(C39) + 4, 8) -> 01000088 | D40: MCTR_CUST_CTR2 | E40: Customer defined Monotonic counter 2
C41: =DEC2HEX(HEX2DEC(C40) + 4, 8) -> 0100008C | D41: MCTR_CUST_CTR3 | E41: Customer defined Monotonic counter 3
...

Sheet IFR0 (customer 3P02G)
A1: Protected Flash Region | E1: 31 | F1: =E1-1 -> 30 | G1: =F1-1 -> 29 | H1: =G1-1 -> 28 | I1: =H1-1 -> 27 | J1: =I1-1 -> 26 | K1: =J1-1 -> 25 | L1: =K1-1 -> 24 | M1: =L1-1 -> 23 | ... AJ1: =AI1-1 -> 0
E3: +3 | M3: +2 | U3: +1 | AC3: +0
E4: 31 | F4: =E4-1 -> 30 | G4: =F4-1 -> 29 | H4: =G4-1 -> 28 | I4: =H4-1 -> 27 | J4: =I4-1 -> 26 | K4: =J4-1 -> 25 | L4: =K4-1 -> 24 | M4: =L4-1 -> 23 | ... AJ4: =AI4-1 -> 0
B5: Word Address (HEX) | C5: Byte Address (HEX) | D5: Field Description
A6: Customer Field Programmable Area (CFPA) | B6: 100000 | C6: =DEC2HEX(HEX2DEC($B$6)*16, 8) -> 01000000 | D6: Header | E6: Header | U6: INV_CFPA_LC_STATE[7:0] | AC6: CFPA_LC_STATE[7:0]
C7: =DEC2HEX(HEX2DEC(C6) + 4, 8) -> 01000004 | D7: CFPA_PAGE_VERSION | E7: DICE_UPD | F7: DICE_KEY_UPD_ALIAS | G7: CMPA_UPD | J7: Reserved | K7: IMG_UPD | M7: CFPA page version (Monotonic counter)
C8: =DEC2HEX(HEX2DEC(C7) + 4, 8) -> 01000008 | D8: Secure_FW_Version | E8: Reserved | U8: Secure firmware version (Monotonic counter)
C9: =DEC2HEX(HEX2DEC(C8) + 4, 8) -> 0100000C | D9: NS_FW_Version | E9: Non Secure firmware version (Monotonic counter)
B10: =DEC2HEX(HEX2DEC(B6) + 1) -> 100001 | C10: =DEC2HEX(HEX2DEC(C9) + 4, 8) -> 01000010 | D10: reserved | E10: Reserved for future use.
C11: =DEC2HEX(HEX2DEC(C10) + 4, 8) -> 01000014 | D11: SECBOOT_FLAGS | E11: OEM_RETURN_ERASE_DONE | I11: Reserved | AC11: RoTK3_EN | AE11: RoTK2_EN | AG11: RoTK1_EN | AI11: RoTK0_EN
C12: =DEC2HEX(HEX2DEC(C11) + 4, 8) -> 01000018 | D12: IMAGE_KEY_REVOKE | E12: RESERVED | M12: Image key revocation ID (Monotonic counter)
C13: =DEC2HEX(HEX2DEC(C12) + 4, 8) -> 0100001C | D13: LP_VECTOR_ADDR | E13: LP_VECTOR_ADDR
B14: =DEC2HEX(HEX2DEC(B10) + 1) -> 100002 | C14: =DEC2HEX(HEX2DEC(C13) + 4, 8) -> 01000020 | D14: DBG_REVOKE_VU | E14: Inverse value of [15:0] | U14: Debug certificate revocation counter (monotonic counter)
C15: =DEC2HEX(HEX2DEC(C14) + 4, 8) -> 01000024 | D15: DCFG_CC_SOCU_NS_PIN | E15: Inverse value of [15:0] | U15: UUID_CHECK | Z15: CPU1_DBGEN | AA15: CPU1_NIDEN | AB15: ME_CMD_EN | AC15: FA_CMD_EN | AD15: ISP_CMD_EN | AE15: DSP_DBGEN | AF15: 0 | AG15: SPIDEN | AH15: SPNIDEN | AI15: DBGEN | AJ15: NIDEN
C16: =DEC2HEX(HEX2DEC(C15) + 4, 8) -> 01000028 | D16: DCFG_CC_SOCU_NS_DFLT | E16: Inverse value of [15:0] | Z16: CPU1_DBGEN | AA16: CPU1_NIDEN | AB16: ME_CMD_EN | AC16: FA_CMD_EN | AD16: ISP_CMD_EN | AE16: DSP_DBGEN | AF16: 0 | AG16: SPIDEN | AH16: SPNIDEN | AI16: DBGEN | AJ16: NIDEN
C17: =DEC2HEX(HEX2DEC(C16) + 4, 8) -> 0100002C | D17: reserved | E17: Reserved
B18: =DEC2HEX(HEX2DEC(B14) + 1) -> 100003 | C18: =DEC2HEX(HEX2DEC(C17) + 4, 8) -> 01000030 | D18: MCTR_NPX_CTX0 | E18: Erase count for internal Prince region 0 (Monotonic counter)
C19: =DEC2HEX(HEX2DEC(C18) + 4, 8) -> 01000034 | D19: MCTR_NPX_CTX1 | E19: Erase count for internal Prince region 1 (Monotonic counter)
C20: =DEC2HEX(HEX2DEC(C19) + 4, 8) -> 01000038 | D20: MCTR_NPX_CTX2 | E20: Erase count for internal Prince region 2 (Monotonic counter)
C21: =DEC2HEX(HEX2DEC(C20) + 4, 8) -> 0100003C | D21: MCTR_NPX_CTX3 | E21: Erase count for internal Prince region 3 (Monotonic counter)
B22: =DEC2HEX(HEX2DEC(B18) + 1) -> 100004 | C22: =DEC2HEX(HEX2DEC(C21) + 4, 8) -> 01000040 | D22: MCTR_IPED_CTX0 | E22: Erase count for external Prince region 0 (Monotonic counter)
C23: =DEC2HEX(HEX2DEC(C22) + 4, 8) -> 01000044 | D23: MCTR_IPED_CTX1 | E23: Erase count for external Prince region 1 (Monotonic counter)
C24: =DEC2HEX(HEX2DEC(C23) + 4, 8) -> 01000048 | D24: MCTR_IPED_CTX2 | E24: Erase count for external Prince region 2 (Monotonic counter)
C25: =DEC2HEX(HEX2DEC(C24) + 4, 8) -> 0100004C | D25: MCTR_IPED_CTX3 | E25: Erase count for external Prince region 3 (Monotonic counter)
B26: =DEC2HEX(HEX2DEC(B22) + 1) -> 100005 | C26: =DEC2HEX(HEX2DEC(C25) + 4, 8) -> 01000050 | D26: MCTR_IPED_CTX4 | E26: Erase count for external Prince region 4 (Monotonic counter)
C27: =DEC2HEX(HEX2DEC(C26) + 4, 8) -> 01000054 | D27: MCTR_IPED_CTX5 | E27: Erase count for external Prince region 5 (Monotonic counter)
C28: =DEC2HEX(HEX2DEC(C27) + 4, 8) -> 01000058 | D28: MCTR_IPED_CTX6 | E28: Erase count for external Prince region 6 (Monotonic counter)
C29: =DEC2HEX(HEX2DEC(C28) + 4, 8) -> 0100005C | D29: MCTR_IPED_CTX7 | E29: Erase count for external Prince region 7 (Monotonic counter)
B30: =DEC2HEX(HEX2DEC(B26) + 1) -> 100006 | C30: =DEC2HEX(HEX2DEC(C29) + 4, 8) -> 01000060 | D30: ERR_AUTH_FAIL_COUNT | E30: Authentication failure counter during boot, SB3, debug authentication (Monotonic counter)
C31: =DEC2HEX(HEX2DEC(C30) + 4, 8) -> 01000064 | D31: ERR_ITRC_COUNT | E31: Tamper event counter (Any ITRC reset caused by tamper events such as WDT reset, CDOG reset, GDET reset, Tamper pin) (Monotonic counter)
C32: =DEC2HEX(HEX2DEC(C31) + 4, 8) -> 01000068 | D32: reserved | E32: Reserved for future use.
C33: =DEC2HEX(HEX2DEC(C32) + 4, 8) -> 0100006C | D33: reserved | E33: Reserved for future use.
B34: =DEC2HEX(HEX2DEC(B30) + 1) -> 100007 | C34: =DEC2HEX(HEX2DEC(C33) + 4, 8) -> 01000070 | D34: reserved | E34: Reserved for future use.
C35: =DEC2HEX(HEX2DEC(C34) + 4, 8) -> 01000074 | D35: reserved | E35: Reserved for future use.
C36: =DEC2HEX(HEX2DEC(C35) + 4, 8) -> 01000078 | D36: reserved | E36: Reserved for future use.
C37: =DEC2HEX(HEX2DEC(C36) + 4, 8) -> 0100007C | D37: reserved | E37: Reserved for future use.
B38: =DEC2HEX(HEX2DEC(B34) + 1) -> 100008 | C38: =DEC2HEX(HEX2DEC(C37) + 4, 8) -> 01000080 | D38: MCTR_CUST_CTR0 | E38: Customer defined Monotonic counter 0
C39: =DEC2HEX(HEX2DEC(C38) + 4, 8) -> 01000084 | D39: MCTR_CUST_CTR1 | E39: Customer defined Monotonic counter 1
C40: =DEC2HEX(HEX2DEC(C39) + 4, 8) -> 01000088 | D40: MCTR_CUST_CTR2 | E40: Customer defined Monotonic counter 2
C41: =DEC2HEX(HEX2DEC(C40) + 4, 8) -> 0100008C | D41: MCTR_CUST_CTR3 | E41: Customer defined Monotonic counter 3
...

Sheet IFR0 (customer 1P02G)
A1: Protected Flash Region | E1: 31 | F1: =E1-1 -> 30 | G1: =F1-1 -> 29 | H1: =G1-1 -> 28 | I1: =H1-1 -> 27 | J1: =I1-1 -> 26 | K1: =J1-1 -> 25 | L1: =K1-1 -> 24 | M1: =L1-1 -> 23 | ... AJ1: =AI1-1 -> 0
E3: +3 | M3: +2 | U3: +1 | AC3: +0
E4: 31 | F4: =E4-1 -> 30 | G4: =F4-1 -> 29 | H4: =G4-1 -> 28 | I4: =H4-1 -> 27 | J4: =I4-1 -> 26 | K4: =J4-1 -> 25 | L4: =K4-1 -> 24 | M4: =L4-1 -> 23 | ... AJ4: =AI4-1 -> 0
B5: Word Address (HEX) | C5: Byte Address (HEX) | D5: Field Description
A6: Customer Field Programmable Area (CFPA) | B6: 100000 | C6: =DEC2HEX(HEX2DEC($B$6)*16, 8) -> 01000000 | D6: Header | E6: CFPA_HEADER | U6: INV_CFPA_LC_STATE[7:0] | AC6: CFPA_LC_STATE[7:0]
C7: =DEC2HEX(HEX2DEC(C6) + 4, 8) -> 01000004 | D7: CFPA_PAGE_VERSION | E7: DICE_UPD | F7: Reserved | G7: CMPA_UPD | J7: Reserved | K7: IMG_UPD | M7: CFPA page version (Monotonic counter) | AL7: ROM enforces monotonic increment check during CFPA-CMAC page update. If the new counter value is less than the value in active CFPA page, then the update is rejected and CMAC sigining is skipped.
C8: =DEC2HEX(HEX2DEC(C7) + 4, 8) -> 01000008 | D8: Secure_FW_Version | E8: Secure firmware version (Monotonic counter) | AL8: ROM enforces monotonic increment check during CFPA-CMAC page update. If the new counter value is less than the value in active CFPA page, then the update is rejected and CMAC sigining is skipped.
C9: =DEC2HEX(HEX2DEC(C8) + 4, 8) -> 0100000C | D9: NS_FW_Version | E9: Non Secure firmware version (Monotonic counter) | AL9: ROM enforces monotonic increment check during CFPA-CMAC page update. If the new counter value is less than the value in active CFPA page, then the update is rejected and CMAC sigining is skipped.
B10: =DEC2HEX(HEX2DEC(B6) + 1) -> 100001 | C10: =DEC2HEX(HEX2DEC(C9) + 4, 8) -> 01000010 | D10: reserved | E10: Reserved for future use.
C11: =DEC2HEX(HEX2DEC(C10) + 4, 8) -> 01000014 | D11: SECBOOT_FLAGS | E11: OEM_RETURN_ERASE_DONE | I11: Reserved | AC11: RoTK3_EN | AE11: RoTK2_EN | AG11: RoTK1_EN | AI11: RoTK0_EN
C12: =DEC2HEX(HEX2DEC(C11) + 4, 8) -> 01000018 | D12: IMAGE_KEY_REVOKE | E12: RESERVED | M12: Image key revocation ID (Monotonic counter) | AL12: ROM enforces monotonic increment check during CFPA-CMAC update.
C13: =DEC2HEX(HEX2DEC(C12) + 4, 8) -> 0100001C | D13: LP_VECTOR_ADDR | E13: LP_VECTOR_ADDR
B14: =DEC2HEX(HEX2DEC(B10) + 1) -> 100002 | C14: =DEC2HEX(HEX2DEC(C13) + 4, 8) -> 01000020 | D14: DBG_REVOKE_VU | E14: Inverse value of [15:0] | U14: Debug certificate revocation counter (monotonic counter) | AL14: ROM enforces monotonic increment check during CFPA-CMAC update.
C15: =DEC2HEX(HEX2DEC(C14) + 4, 8) -> 01000024 | D15: DCFG_CC_SOCU_NS_PIN | E15: Inverse value of [15:0] | U15: UUID_CHECK | Z15: CPU1_DBGEN | AA15: CPU1_NIDEN | AB15: ME_CMD_EN | AC15: FA_CMD_EN | AD15: ISP_CMD_EN | AE15: DSP_DBGEN | AF15: 0 | AG15: SPIDEN | AH15: SPNIDEN | AI15: DBGEN | AJ15: NIDEN
C16: =DEC2HEX(HEX2DEC(C15) + 4, 8) -> 01000028 | D16: DCFG_CC_SOCU_NS_DFLT | E16: Inverse value of [15:0] | Z16: CPU1_DBGEN | AA16: CPU1_NIDEN | AB16: ME_CMD_EN | AC16: FA_CMD_EN | AD16: ISP_CMD_EN | AE16: DSP_DBGEN | AF16: 0 | AG16: SPIDEN | AH16: SPNIDEN | AI16: DBGEN | AJ16: NIDEN
C17: =DEC2HEX(HEX2DEC(C16) + 4, 8) -> 0100002C | D17: reserved | E17: Reserved
B18: =DEC2HEX(HEX2DEC(B14) + 1) -> 100003 | C18: =DEC2HEX(HEX2DEC(C17) + 4, 8) -> 01000030 | D18: MCTR_NPX_CTX0 | E18: Erase count for internal Prince region 0 (Monotonic counter)
C19: =DEC2HEX(HEX2DEC(C18) + 4, 8) -> 01000034 | D19: MCTR_NPX_CTX1 | E19: Erase count for internal Prince region 1 (Monotonic counter)
C20: =DEC2HEX(HEX2DEC(C19) + 4, 8) -> 01000038 | D20: MCTR_NPX_CTX2 | E20: Erase count for internal Prince region 2 (Monotonic counter)
C21: =DEC2HEX(HEX2DEC(C20) + 4, 8) -> 0100003C | D21: MCTR_NPX_CTX3 | E21: Erase count for internal Prince region 3 (Monotonic counter)
B22: =DEC2HEX(HEX2DEC(B18) + 1) -> 100004 | C22: =DEC2HEX(HEX2DEC(C21) + 4, 8) -> 01000040 | D22: MCTR_IPED_CTX0 | E22: Erase count for external Prince region 0 (Monotonic counter)
C23: =DEC2HEX(HEX2DEC(C22) + 4, 8) -> 01000044 | D23: MCTR_IPED_CTX1 | E23: Erase count for external Prince region 1 (Monotonic counter)
C24: =DEC2HEX(HEX2DEC(C23) + 4, 8) -> 01000048 | D24: MCTR_IPED_CTX2 | E24: Erase count for external Prince region 2 (Monotonic counter)
C25: =DEC2HEX(HEX2DEC(C24) + 4, 8) -> 0100004C | D25: MCTR_IPED_CTX3 | E25: Erase count for external Prince region 3 (Monotonic counter)
B26: =DEC2HEX(HEX2DEC(B22) + 1) -> 100005 | C26: =DEC2HEX(HEX2DEC(C25) + 4, 8) -> 01000050 | D26: MCTR_IPED_CTX4 | E26: Erase count for external Prince region 4 (Monotonic counter)
C27: =DEC2HEX(HEX2DEC(C26) + 4, 8) -> 01000054 | D27: MCTR_IPED_CTX5 | E27: Erase count for external Prince region 5 (Monotonic counter)
C28: =DEC2HEX(HEX2DEC(C27) + 4, 8) -> 01000058 | D28: MCTR_IPED_CTX6 | E28: Erase count for external Prince region 6 (Monotonic counter)
C29: =DEC2HEX(HEX2DEC(C28) + 4, 8) -> 0100005C | D29: MCTR_IPED_CTX7 | E29: Erase count for external Prince region 7 (Monotonic counter)
B30: =DEC2HEX(HEX2DEC(B26) + 1) -> 100006 | C30: =DEC2HEX(HEX2DEC(C29) + 4, 8) -> 01000060 | D30: ERR_AUTH_FAIL_COUNT | E30: Authentication failure counter during boot, SB3, debug authentication (Monotonic counter)
C31: =DEC2HEX(HEX2DEC(C30) + 4, 8) -> 01000064 | D31: ERR_ITRC_COUNT | E31: Tamper event counter (Any ITRC reset caused by tamper events such as WDT reset, CDOG reset, GDET reset, Tamper pin) (Monotonic counter)
C32: =DEC2HEX(HEX2DEC(C31) + 4, 8) -> 01000068 | D32: reserved | E32: Reserved for future use.
C33: =DEC2HEX(HEX2DEC(C32) + 4, 8) -> 0100006C | D33: reserved | E33: Reserved for future use.
B34: =DEC2HEX(HEX2DEC(B30) + 1) -> 100007 | C34: =DEC2HEX(HEX2DEC(C33) + 4, 8) -> 01000070 | D34: reserved | E34: Reserved for future use.
C35: =DEC2HEX(HEX2DEC(C34) + 4, 8) -> 01000074 | D35: reserved | E35: Reserved for future use.
C36: =DEC2HEX(HEX2DEC(C35) + 4, 8) -> 01000078 | D36: reserved | E36: Reserved for future use.
C37: =DEC2HEX(HEX2DEC(C36) + 4, 8) -> 0100007C | D37: reserved | E37: Reserved for future use.
B38: =DEC2HEX(HEX2DEC(B34) + 1) -> 100008 | C38: =DEC2HEX(HEX2DEC(C37) + 4, 8) -> 01000080 | D38: MCTR_CUST_CTR0 | E38: Customer defined Monotonic counter 0 | AL38: ROM enforces monotonic increment check during CFPA-CMAC page update.
C39: =DEC2HEX(HEX2DEC(C38) + 4, 8) -> 01000084 | D39: MCTR_CUST_CTR1 | E39: Customer defined Monotonic counter 1 | AL39: ROM enforces monotonic increment check during CFPA-CMAC page update.
C40: =DEC2HEX(HEX2DEC(C39) + 4, 8) -> 01000088 | D40: MCTR_CUST_CTR2 | E40: Customer defined Monotonic counter 2 | AL40: ROM enforces monotonic increment check during CFPA-CMAC page update.
C41: =DEC2HEX(HEX2DEC(C40) + 4, 8) -> 0100008C | D41: MCTR_CUST_CTR3 | E41: Customer defined Monotonic counter 3 | AL41: ROM enforces monotonic increment check during CFPA-CMAC page update.
...

Sheet IFR0 (customer 1P02G for tool)
A1: Protected Flash Region | E1: 31 | F1: 30 | G1: 29 | H1: 28 | I1: 27 | J1: 26 | K1: 25 | L1: 24 | M1: 23 | N1: 22 | O1: 21 | P1: 20 | Q1: 19 | R1: 18 | S1: 17 | T1: 16 | U1: 15 | V1: 14 | W1: 13 | X1: 12 | Y1: 11 | Z1: 10 | AA1: 9 | AB1: 8 | AC1: 7 | AD1: 6 | AE1: 5 | AF1: 4 | AG1: 3 | AH1: 2 | AI1: 1 | AJ1: 0
E3: +3 | M3: +2 | U3: +1 | AC3: +0
E4: 31 | F4: 30 | G4: 29 | H4: 28 | I4: 27 | J4: 26 | K4: 25 | L4: 24 | M4: 23 | N4: 22 | O4: 21 | P4: 20 | Q4: 19 | R4: 18 | S4: 17 | T4: 16 | U4: 15 | V4: 14 | W4: 13 | X4: 12 | Y4: 11 | Z4: 10 | AA4: 9 | AB4: 8 | AC4: 7 | AD4: 6 | AE4: 5 | AF4: 4 | AG4: 3 | AH4: 2 | AI4: 1 | AJ4: 0
B5: Word Address (HEX) | C5: Byte Address (HEX) | D5: Field Description
A6: Customer Field Programmable Area (CFPA) | B6: 100000 | C6: 01000000 | D6: Header | E6: CFPA_HEADER | U6: INV_CFPA_LC_STATE[7:0] | AC6: CFPA_LC_STATE[7:0]
C7: 01000004 | D7: CFPA_PAGE_VERSION | E7: DICE_UPD | F7: Reserved | G7: CMPA_UPD | J7: Reserved | K7: IMG_UPD | M7: CFPA page version (Monotonic counter, should start from 1)
C8: 01000008 | D8: Secure_FW_Version | E8: Reserved | U8: Secure firmware version (Monotonic counter)
C9: 0100000C | D9: NS_FW_Version | E9: Non Secure firmware version (Monotonic counter)
B10: 100001 | C10: 01000010 | D10: reserved | E10: Reserved for future use.
C11: 01000014 | D11: SECBOOT_FLAGS | E11: OEM_RETURN_ERASE_DONE | I11: Reserved | AC11: RoTK3_EN | AE11: RoTK2_EN | AG11: RoTK1_EN | AI11: RoTK0_EN
C12: 01000018 | D12: IMAGE_KEY_REVOKE | E12: RESERVED | M12: Image key revocation ID (Monotonic counter)
C13: 0100001C | D13: LP_VECTOR_ADDR | E13: LP_VECTOR_ADDR
B14: 100002 | C14: 01000020 | D14: DBG_REVOKE_VU | E14: Inverse value of [15:0] | U14: Debug certificate revocation counter (monotonic counter)
C15: 01000024 | D15: DCFG_CC_SOCU_NS_PIN | E15: Inverse value of [15:0] | U15: UUID_CHECK | Z15: CPU1_DBGEN | AA15: CPU1_NIDEN | AB15: ME_CMD_EN | AC15: FA_CMD_EN | AD15: ISP_CMD_EN | AE15: DSP_DBGEN | AF15: 0 | AG15: SPIDEN | AH15: SPNIDEN | AI15: DBGEN | AJ15: NIDEN
C16: 01000028 | D16: DCFG_CC_SOCU_NS_DFLT | E16: Inverse value of [15:0] | Z16: CPU1_DBGEN | AA16: CPU1_NIDEN | AB16: ME_CMD_EN | AC16: FA_CMD_EN | AD16: ISP_CMD_EN | AE16: DSP_DBGEN | AF16: 0 | AG16: SPIDEN | AH16: SPNIDEN | AI16: DBGEN | AJ16: NIDEN
C17: 0100002C | D17: reserved | E17: Reserved
B18: 100003 | C18: 01000030 | D18: MCTR_NPX_CTX0 | E18: Erase count for internal Prince region 0 (Monotonic counter)
C19: 01000034 | D19: MCTR_NPX_CTX1 | E19: Erase count for internal Prince region 1 (Monotonic counter)
C20: 01000038 | D20: MCTR_NPX_CTX2 | E20: Erase count for internal Prince region 2 (Monotonic counter)
C21: 0100003C | D21: MCTR_NPX_CTX3 | E21: Erase count for internal Prince region 3 (Monotonic counter)
B22: 100004 | C22: 01000040 | D22: MCTR_IPED_CTX0 | E22: Erase count for external Prince region 0 (Monotonic counter)
C23: 01000044 | D23: MCTR_IPED_CTX1 | E23: Erase count for external Prince region 1 (Monotonic counter)
C24: 01000048 | D24: MCTR_IPED_CTX2 | E24: Erase count for external Prince region 2 (Monotonic counter)
C25: 0100004C | D25: MCTR_IPED_CTX3 | E25: Erase count for external Prince region 3 (Monotonic counter)
B26: 100005 | C26: 01000050 | D26: MCTR_IPED_CTX4 | E26: Erase count for external Prince region 4 (Monotonic counter)
C27: 01000054 | D27: MCTR_IPED_CTX5 | E27: Erase count for external Prince region 5 (Monotonic counter)
C28: 01000058 | D28: MCTR_IPED_CTX6 | E28: Erase count for external Prince region 6 (Monotonic counter)
C29: 0100005C | D29: MCTR_IPED_CTX7 | E29: Erase count for external Prince region 7 (Monotonic counter)
B30: 100006 | C30: 01000060 | D30: ERR_AUTH_FAIL_COUNT | E30: Authentication failure counter during boot, SB3, debug authentication (Monotonic counter)
C31: 01000064 | D31: ERR_ITRC_COUNT | E31: Tamper event counter (Any ITRC reset caused by tamper events such as WDT reset, CDOG reset, GDET reset, Tamper pin) (Monotonic counter)
C32: 01000068 | D32: reserved | E32: Reserved for future use.
C33: 0100006C | D33: reserved | E33: Reserved for future use.
B34: 100007 | C34: 01000070 | D34: reserved | E34: Reserved for future use.
C35: 01000074 | D35: reserved | E35: Reserved for future use.
C36: 01000078 | D36: reserved | E36: Reserved for future use.
C37: 0100007C | D37: reserved | E37: Reserved for future use.
B38: 100008 | C38: 01000080 | D38: MCTR_CUST_CTR0 | E38: Customer defined Monotonic counter 0
C39: 01000084 | D39: MCTR_CUST_CTR1 | E39: Customer defined Monotonic counter 1
C40: 01000088 | D40: MCTR_CUST_CTR2 | E40: Customer defined Monotonic counter 2
C41: 0100008C | D41: MCTR_CUST_CTR3 | E41: Customer defined Monotonic counter 3
...

Sheet IFR1 (customer)
B1: IFR1 Address | C1: Field name | D1: Field Description
B3: 0x0110_0000 - 0x0110_000F | C3: UUID[127:0] | D3: Universal Unique Identifier (UUID) programmed per part as per RFC4122 version 5 specification.
B4: 0x0110_0010 - 0x0110_001F | C4: ECID[127:0] | D4: NXP's Electronic Chip Identifier(ECID) used for identifying manufacturing batch the part belongs.
B5: 0x0110_0020 - 0x0110_007F | C5: ELS_TRNG_CONFIG | D5: TRNG configuration data used for initializing the entropy source in ELS subsystem. Only first 84 bytes are used. By default boot ROM initializes the entropy source on start-up. But this data can be used to re-initialize ELS, when the ELS susbsytem is reset without complete chip reset.
B6: 0x0110_0080 - 0x0110_008F | C6: Reserved
B7: 0x0110_0090 - 0x0110_009F | C7: GDET_CONFIG0 | D7: Digital glitch detector 0 configuration used by boot ROM.
B8: 0x0110_00A0 - 0x0110_00AF | C8: GDET_CONFIG1 | D8: Digital glitch detector 1 configuration used by boot ROM.
B9: 0x0110_00B0 - 0x0110_01FF | C9: Reserved
B10: 0x0110_0200 - 0x0110_05FF | C10: PUF_ACTIV_CODE | D10: PUF activation code 1000 bytes + 24 bytes header/padding used by boot ROM to initilize SRAM PUF.
B11: 0x0110_0600 - 0x0110_0BFF | C11: NXP_DEV_CERT | D11: NXP signed device identity certificate in compressed binary format.
B12: 0x0110_0C00 - 0x0110_0FFF | C12: Reserved

Sheet nirvana1_ifr1_1P02G
B1: NMPA & NXP KEY AREA | C1: IFR Signal | D1: MSB | E1: LSB | F1: Width | G1: Instance | H1: Inverted | I1: Pin | J1: IFR1 Phrase Offset (hex) | K1: XADR | L1: YADR | M1: Register Field | N1: NMPA & NXP KEY AREA Field | O1: Default Trim Value | P1: Trim Source (M=Mask,P=Part,D=Die) | Q1: Production value | R1: Approved | S1: Description | T1: ES2/ Responsible | U1: A1 CES samples | V1: =nirvana1_phantom_1P02G!E3 -> MCXN947VDFT | W1: =nirvana1_phantom_1P02G!F3 -> MCXN947VPBT | X1: =nirvana1_phantom_1P02G!G3 -> MCXN947VKLT | Y1: =nirvana1_phantom_1P02G!I3 -> MCXN946VDFT | Z1: =nirvana1_phantom_1P02G!J3 -> MCXN946VPBT | AA1: =nirvana1_phantom_1P02G!K3 -> MCXN946VKLT | AB1: =nirvana1_phantom_1P02G!M3 -> MCXN547VDFT | AC1: =nirvana1_phantom_1P02G!N3 -> MCXN547VPBT | AD1: =nirvana1_phantom_1P02G!O3 -> MCXN547VKLT | AE1: =nirvana1_phantom_1P02G!Q3 -> MCXN546VDFT | AF1: =nirvana1_phantom_1P02G!R3 -> MCXN546VPBT | AG1: =nirvana1_phantom_1P02G!S3 -> MCXN546VKLT | AH1: =nirvana1_phantom_1P02G!T3 -> MCXN546VABR | AI1: =nirvana1_phantom_1P02G!U3 -> MCXN527VDFT | AJ1: =nirvana1_phantom_1P02G!V3 -> MCXN527VKLT | BR1: Non-Secure
V2: =nirvana1_phantom_1P02G!E3 -> MCXN947VDFT | W2: =nirvana1_phantom_1P02G!F3 -> MCXN947VPBT | X2: =nirvana1_phantom_1P02G!G3 -> MCXN947VKLT | Y2: =nirvana1_phantom_1P02G!I3 -> MCXN946VDFT | Z2: =nirvana1_phantom_1P02G!J3 -> MCXN946VPBT | AA2: =nirvana1_phantom_1P02G!K3 -> MCXN946VKLT | AB2: =nirvana1_phantom_1P02G!M3 -> MCXN547VDFT | AC2: =nirvana1_phantom_1P02G!N3 -> MCXN547VPBT | AD2: =nirvana1_phantom_1P02G!O3 -> MCXN547VKLT | AE2: =nirvana1_phantom_1P02G!Q3 -> MCXN546VDFT | AF2: =nirvana1_phantom_1P02G!R3 -> MCXN546VPBT | AG2: =nirvana1_phantom_1P02G!S3 -> MCXN546VKLT | AH2: =nirvana1_phantom_1P02G!T3 -> MCXN546VABR | AI2: =nirvana1_phantom_1P02G!U3 -> MCXN527VDFT | AJ2: =nirvana1_phantom_1P02G!V3 -> MCXN527VKLT | AK2: =nirvana1_phantom_1P02G!X3 -> MCXN526VDFT | AL2: =nirvana1_phantom_1P02G!Y3 -> MCXN526VKLT | AM2: =nirvana1_phantom_1P02G!AA3 -> MCXN556SCDFT | AN2: =nirvana1_phantom_1P02G!AB3 -> MCXN247VDFT | AO2: =nirvana1_phantom_1P02G!AC3 -> MCXN247VKLT | AP2: =nirvana1_phantom_1P02G!AD3 -> MCXN247VPBT | AQ2: =nirvana1_phantom_1P02G!AE3 -> MCXN247VABR | AR2: =nirvana1_phantom_1P02G!AG3 -> MCXN537VDFT | AS2: =nirvana1_phantom_1P02G!AH3 -> MCXN537VPBT | AT2: =nirvana1_phantom_1P02G!AI3 -> MCXN537VKLT | AU2: =nirvana1_phantom_1P02G!AJ3 -> MCXN537VABR | AV2: =nirvana1_phantom_1P02G!AK3 -> MCXN536VDFT | AW2: =nirvana1_phantom_1P02G!AL3 -> MCXN536VPBT | AX2: =nirvana1_phantom_1P02G!AM3 -> MCXN536VKLT | AY2: =nirvana1_phantom_1P02G!AN3 -> MCXN536VABR | ... BQ2: =nirvana1_phantom_1P02G!BF3 -> 0 | BR2: =nirvana1_phantom_1P02G!E19 -> 4'h8 | BS2: =nirvana1_phantom_1P02G!F19 -> 4'h8 | BT2: =nirvana1_phantom_1P02G!G19 -> 4'h8 | BU2: =nirvana1_phantom_1P02G!I19 -> 4'h6 | BV2: =nirvana1_phantom_1P02G!J19 -> 4'h6 | BW2: =nirvana1_phantom_1P02G!K19 -> 4'h6 | BX2: =nirvana1_phantom_1P02G!M19 -> 4'h8 | BY2: =nirvana1_phantom_1P02G!N19 -> 4'h8 | BZ2: =nirvana1_phantom_1P02G!O19 -> 4'h8 | CA2: =nirvana1_phantom_1P02G!Q19 -> 4'h6 | CB2: =nirvana1_phantom_1P02G!R19 -> 4'h6 | CC2: =nirvana1_phantom_1P02G!S19 -> 4'h6 | CD2: =nirvana1_phantom_1P02G!T19 -> 4'h6 | CE2: =nirvana1_phantom_1P02G!U19 -> 4'h8 | CF2: =nirvana1_phantom_1P02G!V19 -> 4'h8 | CG2: =nirvana1_phantom_1P02G!X19 -> 4'h6 | CH2: =nirvana1_phantom_1P02G!Y19 -> 4'h6 | CI2: =nirvana1_phantom_1P02G!AA19 -> 4'h6 | CJ2: =nirvana1_phantom_1P02G!AB19 -> 4'h8 | CK2: =nirvana1_phantom_1P02G!AC19 -> 4'h8 | CL2: =nirvana1_phantom_1P02G!AD19 -> 4'h8 | CM2: =nirvana1_phantom_1P02G!AE19 -> 4'h8 | CN2: =nirvana1_phantom_1P02G!AG19 -> 4'h8 | CO2: =nirvana1_phantom_1P02G!AH19 -> 4'h8 | CP2: =nirvana1_phantom_1P02G!AI19 -> 4'h8 | CQ2: =nirvana1_phantom_1P02G!AJ19 -> 4'h8 | CR2: =nirvana1_phantom_1P02G!AK19 -> 4'h6 | CS2: =nirvana1_phantom_1P02G!AL19 -> 4'h6 | CT2: =nirvana1_phantom_1P02G!AM19 -> 4'h6 | CU2: =nirvana1_phantom_1P02G!AN19 -> 4'h6 | ... DM2: =nirvana1_phantom_1P02G!BF19 -> 0
B3: Identity data | D3: 127 | E3: 0 | F3: 128 | G3: UUID | J3: 000 | K3: 0 | L3: 0 | N3: UUID[127:0] | R3: TP-FW | S3: UUID computed as per RFC4122 by test program using ECID. | T3: TE | U3: UUID pattern
D4: 127 | E4: 0 | F4: 128 | G4: ECID | J4: 001 | N4: ECID[127:0] | R4: ATE-Copy ECID | S4: Copy of ECID in open area. Upper portion of IFR1 with ROM patch is hidden during user execution. | T4: TE | U4: ECID
D5: 761 | E5: 0 | F5: 762 | G5: TRNG_CFG0 | J5: 002 | N5: S50_TRNG_CONFIG | Q5: Use A1 TRNG config column | R5: Pending | S5: HMAC signed configuration for TRNG present inside S50. 84 bytes. | T5: Validation, IP, STEC | U5: use A0 TRNG config, until new CZ data avilable
D6: 127 | E6: 0 | F6: 4 | G6: AGDET_CFG | J6: 008 | N6: AGDET_CONFIG | O6: 32'h0000000C | Q6: 32'h0000000C | R6: VA sensistive value which requires retest | S6: Analog glitch detector ripple count threshold. [3:2] Anti pole threshold count [1:0] Threshold Count | T6: Validation, VA | U6: 32'h00000009
E7: 4 | F7: 124 | J7: 008 | N7: Reserved | U7: ffffffff_ffffffff_ffffffff
D8: 127 | E8: 0 | F8: 128 | G8: GDET_CFG0 | J8: 009 | N8: GDET_CONFIG | Q8: Use A1 GDET config value | R8: GDET config tab updated | S8: Digital glitch detector 0 configuration. | T8: Validation | U8: Use A1 typical GDET config until matrix is available
D10: 127 | E10: 0 | F10: 128 | G10: GDET_CFG1 | J10: 00A | Q10: Use A1 GDET config value | S10: Digital glitch detector 1 configuration. | T10: Validation
D11: 63 | E11: 0 | F11: 64 | J11: 00B | N11: PUF_SRAM_CFG | O11: 64'h00000000 | Q11: 32'h00000000 | R11: ATE-PUF_config | S11: PUF SRAM controller initialization settings. | T11: Design - SRAM | U11: 32'h00000000
D12: 127 | E12: 64 | F12: 64 | J12: 00B | N12: Reserved
S13: RESERVED for - powerlib configuration - XTAL 32K CAP bank triming - or NXP provided library configuration data.
D14: 8191 | E14: 0 | F14: 8192 | J14: 020 | N14: PUF_ACTIV_CODE | R14: TP-FW | S14: PUF activation code 1000 bytes + 24 bytes header/padding | T14: LC_FAB | U14: Prov command
J15: 060 | N15: NXP_DEV_CERT | R15: TP-FW | S15: NXP device certificate. 1488 bytes | T15: LC_FAB | U15: Prov command
D17: =E17+F17-1 -> 127 | E17: 0 | F17: 128
D18: =E18+F18-1 -> 31 | E18: 0 | F18: 32 | J18: 0BD | N18: WT1_TEST_VERSION | R18: ATE-NVM | S18: Wafer test 1 information log | T18: TE
D19: =E19+F19-1 -> 63 | E19: =D18+1 -> 32 | F19: 32 | J19: 0BD | N19: WT1_TEST_DATE | R19: ATE-NVM | T19: TE
D20: =E20+F20-1 -> 95 | E20: =D19+1 -> 64 | F20: 32 | J20: 0BD | N20: WT1_TEST_TIME | R20: ATE-NVM | T20: TE
D21: =E21+F21-1 -> 127 | E21: =D20+1 -> 96 | F21: 32 | J21: 0BD | N21: WT1_TEST_INFO | R21: ATE-NVM | T21: TE
D22: =E22+F22-1 -> 31 | E22: 0 | F22: 32 | J22: 0BE | N22: WT2_TEST_VERSION | R22: ATE-NVM | S22: Wafer test 2 information log | T22: TE
D23: =E23+F23-1 -> 63 | E23: =D22+1 -> 32 | F23: 32 | J23: 0BE | N23: WT2_TEST_DATE | R23: ATE-NVM | T23: TE
D24: =E24+F24-1 -> 95 | E24: =D23+1 -> 64 | F24: 32 | J24: 0BE | N24: WT2_TEST_TIME | R24: ATE-NVM | T24: TE
D25: =E25+F25-1 -> 127 | E25: =D24+1 -> 96 | F25: 32 | J25: 0BE | N25: WT2_TEST_INFO | R25: ATE-NVM | T25: TE
D26: =E26+F26-1 -> 31 | E26: 0 | F26: 32 | J26: 0BF | N26: FINAL_TEST_VERSION | R26: ATE-NVM | S26: Final test information log | T26: TE
D27: =E27+F27-1 -> 63 | E27: =D26+1 -> 32 | F27: 32 | J27: 0BF | N27: FINAL_TEST_DATE | R27: ATE-NVM | T27: TE
D28: =E28+F28-1 -> 95 | E28: =D27+1 -> 64 | F28: 32 | J28: 0BF | N28: FINAL_TEST_TIME | R28: ATE-NVM | T28: TE
D29: =E29+F29-1 -> 127 | E29: =D28+1 -> 96 | F29: 32 | J29: 0BF | N29: FINAL_TEST_INFO | R29: ATE-NVM | T29: TE
B30: MSF Test for array 0 | J30: 0C0 | K30: 6 | L30: 0 | P30: P | R30: ATE-NVM | S30: Reserved
D31: 31 | E31: 0 | F31: 32 | J31: 0E0 | K31: 7 | L31: 0 | M31: arraytrim0_0 | O31: 32'h00000000 | P31: D | R31: ATE-NVM | S31: Array Trim - Block 0, Word 0 | T31: TE-NVM
D32: =E32+F32-1 -> 63 | E32: =D31+1 -> 32 | F32: 32 | M32: arraytrim0_1 | O32: 32'h00000000 | R32: ATE-NVM | S32: Array Trim - Block 0, Word 1 | T32: TE-NVM
D33: =E33+F33-1 -> 95 | E33: =D32+1 -> 64 | F33: 32 | M33: arraytrim0_2 | O33: 32'h00000000 | R33: ATE-NVM | S33: Array Trim - Block 0, Word 2 | T33: TE-NVM
D34: =E34+F34-1 -> 127 | E34: =D33+1 -> 96 | F34: 32 | M34: arraytrim0_3 | O34: 32'h00000000 | R34: ATE-NVM | S34: Array Trim - Block 0, Word 3 | T34: TE-NVM
D35: 31 | E35: 0 | F35: 32 | J35: 0E1 | K35: 7 | L35: 1 | M35: repair00_0 | O35: 32'h00000000 | P35: D | R35: ATE-NVM | S35: Repair0 - Block 0, Word 0 | T35: TE-NVM
D36: =E36+F36-1 -> 63 | E36: =D35+1 -> 32 | F36: 32 | M36: repair00_1 | O36: 32'h00000000 | R36: ATE-NVM | S36: Repair0 - Block 0, Word 1 | T36: TE-NVM
D37: =E37+F37-1 -> 95 | E37: =D36+1 -> 64 | F37: 32 | M37: repair00_2 | O37: 32'h00000000 | R37: ATE-NVM | S37: Repair0 - Block 0, Word 2 | T37: TE-NVM
D38: =E38+F38-1 -> 127 | E38: =D37+1 -> 96 | F38: 32 | M38: repair00_3 | O38: 32'h00000000 | R38: ATE-NVM | S38: Repair0 - Block 0, Word 3 | T38: TE-NVM
D39: 31 | E39: 0 | F39: 32 | J39: 0E2 | K39: 7 | L39: 2 | M39: repair01_0 | O39: 32'h00000000 | P39: D | R39: ATE-NVM | S39: Repair1 - Block 0, Word 0 | T39: TE-NVM
D40: =E40+F40-1 -> 63 | E40: =D39+1 -> 32 | F40: 32 | M40: repair01_1 | O40: 32'h00000000 | R40: ATE-NVM | S40: Repair1 - Block 0, Word 1 | T40: TE-NVM
D41: =E41+F41-1 -> 95 | E41: =D40+1 -> 64 | F41: 32 | M41: repair01_2 | O41: 32'h00000000 | R41: ATE-NVM | S41: Repair1 - Block 0, Word 2 | T41: TE-NVM
D42: =E42+F42-1 -> 127 | E42: =D41+1 -> 96 | F42: 32 | M42: repair01_3 | O42: 32'h00000000 | R42: ATE-NVM | S42: Repair1 - Block 0, Word 3 | T42: TE-NVM
...

Sheet nirvana1_ifr1_2P02G
B1: NMPA & NXP KEY AREA | C1: IFR Signal | D1: MSB | E1: LSB | F1: Width | G1: Instance | H1: Inverted | I1: Pin | J1: IFR1 Phrase Offset (hex) | K1: XADR | L1: YADR | M1: Register Field | N1: NMPA & NXP KEY AREA Field | O1: Default Trim Value | P1: Trim Source (M=Mask,P=Part,D=Die) | Q1: Production value | R1: Approved | S1: Description | T1: ES2/ Responsible | U1: A1 CES samples | V1: =nirvana1_phantom_1P02G!E3 -> MCXN947VDFT | W1: =nirvana1_phantom_1P02G!F3 -> MCXN947VPBT | X1: =nirvana1_phantom_1P02G!G3 -> MCXN947VKLT | Y1: =nirvana1_phantom_1P02G!I3 -> MCXN946VDFT | Z1: =nirvana1_phantom_1P02G!J3 -> MCXN946VPBT | AA1: =nirvana1_phantom_1P02G!K3 -> MCXN946VKLT | AB1: =nirvana1_phantom_1P02G!M3 -> MCXN547VDFT | AC1: =nirvana1_phantom_1P02G!N3 -> MCXN547VPBT | AD1: =nirvana1_phantom_1P02G!O3 -> MCXN547VKLT | AE1: =nirvana1_phantom_1P02G!Q3 -> MCXN546VDFT | AF1: =nirvana1_phantom_1P02G!R3 -> MCXN546VPBT | AG1: =nirvana1_phantom_1P02G!S3 -> MCXN546VKLT | AH1: =nirvana1_phantom_1P02G!T3 -> MCXN546VABR | AI1: =nirvana1_phantom_1P02G!U3 -> MCXN527VDFT | AJ1: =nirvana1_phantom_1P02G!V3 -> MCXN527VKLT | BR1: Non-Secure
V2: =nirvana1_phantom_1P02G!E3 -> MCXN947VDFT | W2: =nirvana1_phantom_1P02G!F3 -> MCXN947VPBT | X2: =nirvana1_phantom_1P02G!G3 -> MCXN947VKLT | Y2: =nirvana1_phantom_1P02G!I3 -> MCXN946VDFT | Z2: =nirvana1_phantom_1P02G!J3 -> MCXN946VPBT | AA2: =nirvana1_phantom_1P02G!K3 -> MCXN946VKLT | AB2: =nirvana1_phantom_1P02G!M3 -> MCXN547VDFT | AC2: =nirvana1_phantom_1P02G!N3 -> MCXN547VPBT | AD2: =nirvana1_phantom_1P02G!O3 -> MCXN547VKLT | AE2: =nirvana1_phantom_1P02G!Q3 -> MCXN546VDFT | AF2: =nirvana1_phantom_1P02G!R3 -> MCXN546VPBT | AG2: =nirvana1_phantom_1P02G!S3 -> MCXN546VKLT | AH2: =nirvana1_phantom_1P02G!T3 -> MCXN546VABR | AI2: =nirvana1_phantom_1P02G!U3 -> MCXN527VDFT | AJ2: =nirvana1_phantom_1P02G!V3 -> MCXN527VKLT | AK2: =nirvana1_phantom_1P02G!X3 -> MCXN526VDFT | AL2: =nirvana1_phantom_1P02G!Y3 -> MCXN526VKLT | AM2: =nirvana1_phantom_1P02G!AA3 -> MCXN556SCDFT | AN2: =nirvana1_phantom_1P02G!AB3 -> MCXN247VDFT | AO2: =nirvana1_phantom_1P02G!AC3 -> MCXN247VKLT | AP2: =nirvana1_phantom_1P02G!AD3 -> MCXN247VPBT | AQ2: =nirvana1_phantom_1P02G!AE3 -> MCXN247VABR | AR2: =nirvana1_phantom_1P02G!AG3 -> MCXN537VDFT | AS2: =nirvana1_phantom_1P02G!AH3 -> MCXN537VPBT | AT2: =nirvana1_phantom_1P02G!AI3 -> MCXN537VKLT | AU2: =nirvana1_phantom_1P02G!AJ3 -> MCXN537VABR | AV2: =nirvana1_phantom_1P02G!AK3 -> MCXN536VDFT | AW2: =nirvana1_phantom_1P02G!AL3 -> MCXN536VPBT | AX2: =nirvana1_phantom_1P02G!AM3 -> MCXN536VKLT | AY2: =nirvana1_phantom_1P02G!AN3 -> MCXN536VABR | ... BQ2: =nirvana1_phantom_1P02G!BF3 -> 0 | BR2: =nirvana1_phantom_1P02G!E19 -> 4'h8 | BS2: =nirvana1_phantom_1P02G!F19 -> 4'h8 | BT2: =nirvana1_phantom_1P02G!G19 -> 4'h8 | BU2: =nirvana1_phantom_1P02G!I19 -> 4'h6 | BV2: =nirvana1_phantom_1P02G!J19 -> 4'h6 | BW2: =nirvana1_phantom_1P02G!K19 -> 4'h6 | BX2: =nirvana1_phantom_1P02G!M19 -> 4'h8 | BY2: =nirvana1_phantom_1P02G!N19 -> 4'h8 | BZ2: =nirvana1_phantom_1P02G!O19 -> 4'h8 | CA2: =nirvana1_phantom_1P02G!Q19 -> 4'h6 | CB2: =nirvana1_phantom_1P02G!R19 -> 4'h6 | CC2: =nirvana1_phantom_1P02G!S19 -> 4'h6 | CD2: =nirvana1_phantom_1P02G!T19 -> 4'h6 | CE2: =nirvana1_phantom_1P02G!U19 -> 4'h8 | CF2: =nirvana1_phantom_1P02G!V19 -> 4'h8 | CG2: =nirvana1_phantom_1P02G!X19 -> 4'h6 | CH2: =nirvana1_phantom_1P02G!Y19 -> 4'h6 | CI2: =nirvana1_phantom_1P02G!AA19 -> 4'h6 | CJ2: =nirvana1_phantom_1P02G!AB19 -> 4'h8 | CK2: =nirvana1_phantom_1P02G!AC19 -> 4'h8 | CL2: =nirvana1_phantom_1P02G!AD19 -> 4'h8 | CM2: =nirvana1_phantom_1P02G!AE19 -> 4'h8 | CN2: =nirvana1_phantom_1P02G!AG19 -> 4'h8 | CO2: =nirvana1_phantom_1P02G!AH19 -> 4'h8 | CP2: =nirvana1_phantom_1P02G!AI19 -> 4'h8 | CQ2: =nirvana1_phantom_1P02G!AJ19 -> 4'h8 | CR2: =nirvana1_phantom_1P02G!AK19 -> 4'h6 | CS2: =nirvana1_phantom_1P02G!AL19 -> 4'h6 | CT2: =nirvana1_phantom_1P02G!AM19 -> 4'h6 | CU2: =nirvana1_phantom_1P02G!AN19 -> 4'h6 | ... DM2: =nirvana1_phantom_1P02G!BF19 -> 0
B3: Identity data | D3: 127 | E3: 0 | F3: 128 | G3: UUID | J3: 000 | K3: 0 | L3: 0 | N3: UUID[127:0] | R3: TP-FW | S3: UUID computed as per RFC4122 by test program using ECID. | T3: TE | U3: UUID pattern
D4: 127 | E4: 0 | F4: 128 | G4: ECID | J4: 001 | N4: ECID[127:0] | R4: ATE-Copy ECID | S4: Copy of ECID in open area. Upper portion of IFR1 with ROM patch is hidden during user execution. | T4: TE | U4: ECID
D5: 761 | E5: 0 | F5: 762 | G5: TRNG_CFG0 | J5: 002 | N5: S50_TRNG_CONFIG | Q5: Use A1 TRNG config column | R5: Pending | S5: HMAC signed configuration for TRNG present inside S50. 84 bytes. | T5: Validation, IP, STEC | U5: use A0 TRNG config, until new CZ data avilable
D6: 127 | E6: 0 | F6: 4 | G6: AGDET_CFG | J6: 008 | N6: AGDET_CONFIG | O6: 32'h0000000C | Q6: 32'h0000000C | R6: VA sensistive value which requires retest | S6: Analog glitch detector ripple count threshold. [3:2] Anti pole threshold count [1:0] Threshold Count | T6: Validation, VA | U6: 32'h00000009
E7: 4 | F7: 124 | J7: 008 | N7: Reserved | U7: ffffffff_ffffffff_ffffffff
D8: 127 | E8: 0 | F8: 128 | G8: GDET_CFG0 | J8: 009 | N8: GDET_CONFIG | Q8: Use A1 GDET config value | R8: GDET config tab updated | S8: Digital glitch detector 0 configuration. | T8: Validation | U8: Use A1 typical GDET config until matrix is available
D10: 127 | E10: 0 | F10: 128 | G10: GDET_CFG1 | J10: 00A | Q10: Use A1 GDET config value | S10: Digital glitch detector 1 configuration. | T10: Validation
D11: 63 | E11: 0 | F11: 64 | J11: 00B | N11: PUF_SRAM_CFG | O11: 64'h00000000 | Q11: 32'h00000000 | R11: ATE-PUF_config | S11: PUF SRAM controller initialization settings. | T11: Design - SRAM | U11: 32'h00000000
D12: 127 | E12: 64 | F12: 64 | J12: 00B | N12: Reserved
S13: RESERVED for - powerlib configuration - XTAL 32K CAP bank triming - or NXP provided library configuration data.
D14: 8191 | E14: 0 | F14: 8192 | J14: 020 | N14: PUF_ACTIV_CODE | R14: TP-FW | S14: PUF activation code 1000 bytes + 24 bytes header/padding | T14: LC_FAB | U14: Prov command
J15: 060 | N15: NXP_DEV_CERT | R15: TP-FW | S15: NXP device certificate. 1488 bytes | T15: LC_FAB | U15: Prov command
D17: =E17+F17-1 -> 127 | E17: 0 | F17: 128
D18: =E18+F18-1 -> 31 | E18: 0 | F18: 32 | J18: 0BD | N18: WT1_TEST_VERSION | R18: ATE-NVM | S18: Wafer test 1 information log | T18: TE
D19: =E19+F19-1 -> 63 | E19: =D18+1 -> 32 | F19: 32 | J19: 0BD | N19: WT1_TEST_DATE | R19: ATE-NVM | T19: TE
D20: =E20+F20-1 -> 95 | E20: =D19+1 -> 64 | F20: 32 | J20: 0BD | N20: WT1_TEST_TIME | R20: ATE-NVM | T20: TE
D21: =E21+F21-1 -> 127 | E21: =D20+1 -> 96 | F21: 32 | J21: 0BD | N21: WT1_TEST_INFO | R21: ATE-NVM | T21: TE
D22: =E22+F22-1 -> 31 | E22: 0 | F22: 32 | J22: 0BE | N22: WT2_TEST_VERSION | R22: ATE-NVM | S22: Wafer test 2 information log | T22: TE
D23: =E23+F23-1 -> 63 | E23: =D22+1 -> 32 | F23: 32 | J23: 0BE | N23: WT2_TEST_DATE | R23: ATE-NVM | T23: TE
D24: =E24+F24-1 -> 95 | E24: =D23+1 -> 64 | F24: 32 | J24: 0BE | N24: WT2_TEST_TIME | R24: ATE-NVM | T24: TE
D25: =E25+F25-1 -> 127 | E25: =D24+1 -> 96 | F25: 32 | J25: 0BE | N25: WT2_TEST_INFO | R25: ATE-NVM | T25: TE
D26: =E26+F26-1 -> 31 | E26: 0 | F26: 32 | J26: 0BF | N26: FINAL_TEST_VERSION | R26: ATE-NVM | S26: Final test information log | T26: TE
D27: =E27+F27-1 -> 63 | E27: =D26+1 -> 32 | F27: 32 | J27: 0BF | N27: FINAL_TEST_DATE | R27: ATE-NVM | T27: TE
D28: =E28+F28-1 -> 95 | E28: =D27+1 -> 64 | F28: 32 | J28: 0BF | N28: FINAL_TEST_TIME | R28: ATE-NVM | T28: TE
D29: =E29+F29-1 -> 127 | E29: =D28+1 -> 96 | F29: 32 | J29: 0BF | N29: FINAL_TEST_INFO | R29: ATE-NVM | T29: TE
B30: MSF Test for array 0 | J30: 0C0 | K30: 6 | L30: 0 | P30: P | R30: ATE-NVM | S30: Reserved
D31: 31 | E31: 0 | F31: 32 | J31: 0E0 | K31: 7 | L31: 0 | M31: arraytrim0_0 | O31: 32'h00000000 | P31: D | R31: ATE-NVM | S31: Array Trim - Block 0, Word 0 | T31: TE-NVM
D32: =E32+F32-1 -> 63 | E32: =D31+1 -> 32 | F32: 32 | M32: arraytrim0_1 | O32: 32'h00000000 | R32: ATE-NVM | S32: Array Trim - Block 0, Word 1 | T32: TE-NVM
D33: =E33+F33-1 -> 95 | E33: =D32+1 -> 64 | F33: 32 | M33: arraytrim0_2 | O33: 32'h00000000 | R33: ATE-NVM | S33: Array Trim - Block 0, Word 2 | T33: TE-NVM
D34: =E34+F34-1 -> 127 | E34: =D33+1 -> 96 | F34: 32 | M34: arraytrim0_3 | O34: 32'h00000000 | R34: ATE-NVM | S34: Array Trim - Block 0, Word 3 | T34: TE-NVM
D35: 31 | E35: 0 | F35: 32 | J35: 0E1 | K35: 7 | L35: 1 | M35: repair00_0 | O35: 32'h00000000 | P35: D | R35: ATE-NVM | S35: Repair0 - Block 0, Word 0 | T35: TE-NVM
D36: =E36+F36-1 -> 63 | E36: =D35+1 -> 32 | F36: 32 | M36: repair00_1 | O36: 32'h00000000 | R36: ATE-NVM | S36: Repair0 - Block 0, Word 1 | T36: TE-NVM
D37: =E37+F37-1 -> 95 | E37: =D36+1 -> 64 | F37: 32 | M37: repair00_2 | O37: 32'h00000000 | R37: ATE-NVM | S37: Repair0 - Block 0, Word 2 | T37: TE-NVM
D38: =E38+F38-1 -> 127 | E38: =D37+1 -> 96 | F38: 32 | M38: repair00_3 | O38: 32'h00000000 | R38: ATE-NVM | S38: Repair0 - Block 0, Word 3 | T38: TE-NVM
D39: 31 | E39: 0 | F39: 32 | J39: 0E2 | K39: 7 | L39: 2 | M39: repair01_0 | O39: 32'h00000000 | P39: D | R39: ATE-NVM | S39: Repair1 - Block 0, Word 0 | T39: TE-NVM
D40: =E40+F40-1 -> 63 | E40: =D39+1 -> 32 | F40: 32 | M40: repair01_1 | O40: 32'h00000000 | R40: ATE-NVM | S40: Repair1 - Block 0, Word 1 | T40: TE-NVM
D41: =E41+F41-1 -> 95 | E41: =D40+1 -> 64 | F41: 32 | M41: repair01_2 | O41: 32'h00000000 | R41: ATE-NVM | S41: Repair1 - Block 0, Word 2 | T41: TE-NVM
D42: =E42+F42-1 -> 127 | E42: =D41+1 -> 96 | F42: 32 | M42: repair01_3 | O42: 32'h00000000 | R42: ATE-NVM | S42: Repair1 - Block 0, Word 3 | T42: TE-NVM
...

Sheet nirvana1_ifr1_3P02G 
B1: NMPA & NXP KEY AREA | C1: IFR Signal | D1: MSB | E1: LSB | F1: Width | G1: Instance | H1: Inverted | I1: Pin | J1: IFR1 Phrase Offset (hex) | K1: XADR | L1: YADR | M1: Register Field | N1: NMPA & NXP KEY AREA Field | O1: Default Trim Value | P1: Trim Source (M=Mask,P=Part,D=Die) | Q1: Production value | R1: Approved | S1: Description | T1: ES2/ Responsible | U1: A1 CES samples | V1: =nirvana1_phantom_1P02G!E3 -> MCXN947VDFT | W1: =nirvana1_phantom_1P02G!F3 -> MCXN947VPBT | X1: =nirvana1_phantom_1P02G!G3 -> MCXN947VKLT | Y1: =nirvana1_phantom_1P02G!I3 -> MCXN946VDFT | Z1: =nirvana1_phantom_1P02G!J3 -> MCXN946VPBT | AA1: =nirvana1_phantom_1P02G!K3 -> MCXN946VKLT | AB1: =nirvana1_phantom_1P02G!M3 -> MCXN547VDFT | AC1: =nirvana1_phantom_1P02G!N3 -> MCXN547VPBT | AD1: =nirvana1_phantom_1P02G!O3 -> MCXN547VKLT | AE1: =nirvana1_phantom_1P02G!Q3 -> MCXN546VDFT | AF1: =nirvana1_phantom_1P02G!R3 -> MCXN546VPBT | AG1: =nirvana1_phantom_1P02G!S3 -> MCXN546VKLT | AH1: =nirvana1_phantom_1P02G!T3 -> MCXN546VABR | AI1: =nirvana1_phantom_1P02G!U3 -> MCXN527VDFT | AJ1: =nirvana1_phantom_1P02G!V3 -> MCXN527VKLT | BR1: Non-Secure
V2: =nirvana1_phantom_1P02G!E3 -> MCXN947VDFT | W2: =nirvana1_phantom_1P02G!F3 -> MCXN947VPBT | X2: =nirvana1_phantom_1P02G!G3 -> MCXN947VKLT | Y2: =nirvana1_phantom_1P02G!I3 -> MCXN946VDFT | Z2: =nirvana1_phantom_1P02G!J3 -> MCXN946VPBT | AA2: =nirvana1_phantom_1P02G!K3 -> MCXN946VKLT | AB2: =nirvana1_phantom_1P02G!M3 -> MCXN547VDFT | AC2: =nirvana1_phantom_1P02G!N3 -> MCXN547VPBT | AD2: =nirvana1_phantom_1P02G!O3 -> MCXN547VKLT | AE2: =nirvana1_phantom_1P02G!Q3 -> MCXN546VDFT | AF2: =nirvana1_phantom_1P02G!R3 -> MCXN546VPBT | AG2: =nirvana1_phantom_1P02G!S3 -> MCXN546VKLT | AH2: =nirvana1_phantom_1P02G!T3 -> MCXN546VABR | AI2: =nirvana1_phantom_1P02G!U3 -> MCXN527VDFT | AJ2: =nirvana1_phantom_1P02G!V3 -> MCXN527VKLT | AK2: =nirvana1_phantom_1P02G!X3 -> MCXN526VDFT | AL2: =nirvana1_phantom_1P02G!Y3 -> MCXN526VKLT | AM2: =nirvana1_phantom_1P02G!AA3 -> MCXN556SCDFT | AN2: =nirvana1_phantom_1P02G!AB3 -> MCXN247VDFT | AO2: =nirvana1_phantom_1P02G!AC3 -> MCXN247VKLT | AP2: =nirvana1_phantom_1P02G!AD3 -> MCXN247VPBT | AQ2: =nirvana1_phantom_1P02G!AE3 -> MCXN247VABR | AR2: =nirvana1_phantom_1P02G!AG3 -> MCXN537VDFT | AS2: =nirvana1_phantom_1P02G!AH3 -> MCXN537VPBT | AT2: =nirvana1_phantom_1P02G!AI3 -> MCXN537VKLT | AU2: =nirvana1_phantom_1P02G!AJ3 -> MCXN537VABR | AV2: =nirvana1_phantom_1P02G!AK3 -> MCXN536VDFT | AW2: =nirvana1_phantom_1P02G!AL3 -> MCXN536VPBT | AX2: =nirvana1_phantom_1P02G!AM3 -> MCXN536VKLT | AY2: =nirvana1_phantom_1P02G!AN3 -> MCXN536VABR | ... BQ2: =nirvana1_phantom_1P02G!BF3 -> 0 | BR2: =nirvana1_phantom_1P02G!E19 -> 4'h8 | BS2: =nirvana1_phantom_1P02G!F19 -> 4'h8 | BT2: =nirvana1_phantom_1P02G!G19 -> 4'h8 | BU2: =nirvana1_phantom_1P02G!I19 -> 4'h6 | BV2: =nirvana1_phantom_1P02G!J19 -> 4'h6 | BW2: =nirvana1_phantom_1P02G!K19 -> 4'h6 | BX2: =nirvana1_phantom_1P02G!M19 -> 4'h8 | BY2: =nirvana1_phantom_1P02G!N19 -> 4'h8 | BZ2: =nirvana1_phantom_1P02G!O19 -> 4'h8 | CA2: =nirvana1_phantom_1P02G!Q19 -> 4'h6 | CB2: =nirvana1_phantom_1P02G!R19 -> 4'h6 | CC2: =nirvana1_phantom_1P02G!S19 -> 4'h6 | CD2: =nirvana1_phantom_1P02G!T19 -> 4'h6 | CE2: =nirvana1_phantom_1P02G!U19 -> 4'h8 | CF2: =nirvana1_phantom_1P02G!V19 -> 4'h8 | CG2: =nirvana1_phantom_1P02G!X19 -> 4'h6 | CH2: =nirvana1_phantom_1P02G!Y19 -> 4'h6 | CI2: =nirvana1_phantom_1P02G!AA19 -> 4'h6 | CJ2: =nirvana1_phantom_1P02G!AB19 -> 4'h8 | CK2: =nirvana1_phantom_1P02G!AC19 -> 4'h8 | CL2: =nirvana1_phantom_1P02G!AD19 -> 4'h8 | CM2: =nirvana1_phantom_1P02G!AE19 -> 4'h8 | CN2: =nirvana1_phantom_1P02G!AG19 -> 4'h8 | CO2: =nirvana1_phantom_1P02G!AH19 -> 4'h8 | CP2: =nirvana1_phantom_1P02G!AI19 -> 4'h8 | CQ2: =nirvana1_phantom_1P02G!AJ19 -> 4'h8 | CR2: =nirvana1_phantom_1P02G!AK19 -> 4'h6 | CS2: =nirvana1_phantom_1P02G!AL19 -> 4'h6 | CT2: =nirvana1_phantom_1P02G!AM19 -> 4'h6 | CU2: =nirvana1_phantom_1P02G!AN19 -> 4'h6 | ... DM2: =nirvana1_phantom_1P02G!BF19 -> 0
B3: Identity data | D3: 127 | E3: 0 | F3: 128 | G3: UUID | J3: 000 | K3: 0 | L3: 0 | N3: UUID[127:0] | R3: TP-FW | S3: UUID computed as per RFC4122 by test program using ECID. | T3: TE | U3: UUID pattern
D4: 127 | E4: 0 | F4: 128 | G4: ECID | J4: 001 | N4: ECID[127:0] | R4: ATE-Copy ECID | S4: Copy of ECID in open area. Upper portion of IFR1 with ROM patch is hidden during user execution. | T4: TE | U4: ECID
D5: 761 | E5: 0 | F5: 762 | G5: TRNG_CFG0 | J5: 002 | N5: S50_TRNG_CONFIG | Q5: Use A1 TRNG config column | R5: Pending | S5: HMAC signed configuration for TRNG present inside S50. 84 bytes. | T5: Validation, IP, STEC | U5: use A0 TRNG config, until new CZ data avilable
D6: 127 | E6: 0 | F6: 4 | G6: AGDET_CFG | J6: 008 | N6: AGDET_CONFIG | O6: 32'h0000000C | Q6: 32'h0000000C | R6: VA sensistive value which requires retest | S6: Analog glitch detector ripple count threshold. [3:2] Anti pole threshold count [1:0] Threshold Count | T6: Validation, VA | U6: 32'h00000009
E7: 4 | F7: 124 | J7: 008 | N7: Reserved | U7: ffffffff_ffffffff_ffffffff
D8: 127 | E8: 0 | F8: 128 | G8: GDET_CFG0 | J8: 009 | N8: GDET_CONFIG | Q8: Use A1 GDET config value | R8: GDET config tab updated | S8: Digital glitch detector 0 configuration. | T8: Validation | U8: Use A1 typical GDET config until matrix is available
D10: 127 | E10: 0 | F10: 128 | G10: GDET_CFG1 | J10: 00A | Q10: Use A1 GDET config value | S10: Digital glitch detector 1 configuration. | T10: Validation
D11: 63 | E11: 0 | F11: 64 | J11: 00B | N11: PUF_SRAM_CFG | O11: 64'h00000000 | Q11: 32'h00000000 | R11: ATE-PUF_config | S11: PUF SRAM controller initialization settings. | T11: Design - SRAM | U11: 32'h00000000
D12: 127 | E12: 64 | F12: 64 | J12: 00B | N12: Reserved
S13: RESERVED for - powerlib configuration - XTAL 32K CAP bank triming - or NXP provided library configuration data.
D14: 8191 | E14: 0 | F14: 8192 | J14: 020 | N14: PUF_ACTIV_CODE | R14: TP-FW | S14: PUF activation code 1000 bytes + 24 bytes header/padding | T14: LC_FAB | U14: Prov command
J15: 060 | N15: NXP_DEV_CERT | R15: TP-FW | S15: NXP device certificate. 1488 bytes | T15: LC_FAB | U15: Prov command
D17: =E17+F17-1 -> 127 | E17: 0 | F17: 128
D18: =E18+F18-1 -> 31 | E18: 0 | F18: 32 | J18: 0BD | N18: WT1_TEST_VERSION | R18: ATE-NVM | S18: Wafer test 1 information log | T18: TE
D19: =E19+F19-1 -> 63 | E19: =D18+1 -> 32 | F19: 32 | J19: 0BD | N19: WT1_TEST_DATE | R19: ATE-NVM | T19: TE
D20: =E20+F20-1 -> 95 | E20: =D19+1 -> 64 | F20: 32 | J20: 0BD | N20: WT1_TEST_TIME | R20: ATE-NVM | T20: TE
D21: =E21+F21-1 -> 127 | E21: =D20+1 -> 96 | F21: 32 | J21: 0BD | N21: WT1_TEST_INFO | R21: ATE-NVM | T21: TE
D22: =E22+F22-1 -> 31 | E22: 0 | F22: 32 | J22: 0BE | N22: WT2_TEST_VERSION | R22: ATE-NVM | S22: Wafer test 2 information log | T22: TE
D23: =E23+F23-1 -> 63 | E23: =D22+1 -> 32 | F23: 32 | J23: 0BE | N23: WT2_TEST_DATE | R23: ATE-NVM | T23: TE
D24: =E24+F24-1 -> 95 | E24: =D23+1 -> 64 | F24: 32 | J24: 0BE | N24: WT2_TEST_TIME | R24: ATE-NVM | T24: TE
D25: =E25+F25-1 -> 127 | E25: =D24+1 -> 96 | F25: 32 | J25: 0BE | N25: WT2_TEST_INFO | R25: ATE-NVM | T25: TE
D26: =E26+F26-1 -> 31 | E26: 0 | F26: 32 | J26: 0BF | N26: FINAL_TEST_VERSION | R26: ATE-NVM | S26: Final test information log | T26: TE
D27: =E27+F27-1 -> 63 | E27: =D26+1 -> 32 | F27: 32 | J27: 0BF | N27: FINAL_TEST_DATE | R27: ATE-NVM | T27: TE
D28: =E28+F28-1 -> 95 | E28: =D27+1 -> 64 | F28: 32 | J28: 0BF | N28: FINAL_TEST_TIME | R28: ATE-NVM | T28: TE
D29: =E29+F29-1 -> 127 | E29: =D28+1 -> 96 | F29: 32 | J29: 0BF | N29: FINAL_TEST_INFO | R29: ATE-NVM | T29: TE
B30: MSF Test for array 0 | J30: 0C0 | K30: 6 | L30: 0 | P30: P | R30: ATE-NVM | S30: Reserved
D31: 31 | E31: 0 | F31: 32 | J31: 0E0 | K31: 7 | L31: 0 | M31: arraytrim0_0 | O31: 32'h00000000 | P31: D | R31: ATE-NVM | S31: Array Trim - Block 0, Word 0 | T31: TE-NVM
D32: =E32+F32-1 -> 63 | E32: =D31+1 -> 32 | F32: 32 | M32: arraytrim0_1 | O32: 32'h00000000 | R32: ATE-NVM | S32: Array Trim - Block 0, Word 1 | T32: TE-NVM
D33: =E33+F33-1 -> 95 | E33: =D32+1 -> 64 | F33: 32 | M33: arraytrim0_2 | O33: 32'h00000000 | R33: ATE-NVM | S33: Array Trim - Block 0, Word 2 | T33: TE-NVM
D34: =E34+F34-1 -> 127 | E34: =D33+1 -> 96 | F34: 32 | M34: arraytrim0_3 | O34: 32'h00000000 | R34: ATE-NVM | S34: Array Trim - Block 0, Word 3 | T34: TE-NVM
D35: 31 | E35: 0 | F35: 32 | J35: 0E1 | K35: 7 | L35: 1 | M35: repair00_0 | O35: 32'h00000000 | P35: D | R35: ATE-NVM | S35: Repair0 - Block 0, Word 0 | T35: TE-NVM
D36: =E36+F36-1 -> 63 | E36: =D35+1 -> 32 | F36: 32 | M36: repair00_1 | O36: 32'h00000000 | R36: ATE-NVM | S36: Repair0 - Block 0, Word 1 | T36: TE-NVM
D37: =E37+F37-1 -> 95 | E37: =D36+1 -> 64 | F37: 32 | M37: repair00_2 | O37: 32'h00000000 | R37: ATE-NVM | S37: Repair0 - Block 0, Word 2 | T37: TE-NVM
D38: =E38+F38-1 -> 127 | E38: =D37+1 -> 96 | F38: 32 | M38: repair00_3 | O38: 32'h00000000 | R38: ATE-NVM | S38: Repair0 - Block 0, Word 3 | T38: TE-NVM
D39: 31 | E39: 0 | F39: 32 | J39: 0E2 | K39: 7 | L39: 2 | M39: repair01_0 | O39: 32'h00000000 | P39: D | R39: ATE-NVM | S39: Repair1 - Block 0, Word 0 | T39: TE-NVM
D40: =E40+F40-1 -> 63 | E40: =D39+1 -> 32 | F40: 32 | M40: repair01_1 | O40: 32'h00000000 | R40: ATE-NVM | S40: Repair1 - Block 0, Word 1 | T40: TE-NVM
D41: =E41+F41-1 -> 95 | E41: =D40+1 -> 64 | F41: 32 | M41: repair01_2 | O41: 32'h00000000 | R41: ATE-NVM | S41: Repair1 - Block 0, Word 2 | T41: TE-NVM
D42: =E42+F42-1 -> 127 | E42: =D41+1 -> 96 | F42: 32 | M42: repair01_3 | O42: 32'h00000000 | R42: ATE-NVM | S42: Repair1 - Block 0, Word 3 | T42: TE-NVM
...

Sheet GDET Config 1P02G
A1: A1 GDET IFR1 : 0x0110_0090, 0x0110_00A0 | E1: 000000000000_0F_0F_PE_PE_3F_00_PE_00_06_0B
A2: A0 GDET IFR1 : 0x0110_0090, 0x0110_00A0 | E2: 000000000000_0C_0B_PE_PE_1F_00_PE_00_06_0B
